<?xml version="1.0" ?>
<!-- =================================================================================== -->
<!-- |    This document was autogenerated by xacro from model/urdf/hand_standalone.urdf.xacro | -->
<!-- |    EDITING THIS FILE BY HAND IS NOT RECOMMENDED                                 | -->
<!-- =================================================================================== -->
<robot name="floating">
  <link name="floating"/>
  <!-- </xacro:unless> -->
  <!-- base -->
  <joint name="floating_ability_hand_wrist_connector_joint" type="fixed">
    <origin rpy="0 0 0" xyz="0 0 0"/>
    <parent link="floating"/>
    <child link="wrist_connector"/>
  </joint>
  <link name="wrist_connector">
    <visual name="wrist_mesh">
      <geometry>
        <mesh filename="package://psyonic_ability_hand_model/model/meshes/wrist_mount.stl"/>
      </geometry>
    </visual>
  </link>
  <joint name="floating_ability_hand_base_joint" type="fixed">
    <parent link="wrist_connector"/>
    <child link="ability_hand_base"/>
    <origin rpy="0 0.0 0" xyz="0.027 0.0025 -0.025"/>
    <!-- <origin rpy="0 0 0" xyz="0 0 0"/> -->
  </joint>
  <!-- BEGIN HAND -->
  <link name="ability_hand_base">
    <inertial>
      <mass value="0.400"/>
      <inertia ixx="978.26e-6" ixy="87.34e-6" ixz="322.99e-6" iyy="1244.78e-6" iyz="244.74e-6" izz="456.22e-6"/>
      <origin rpy="0 0 0" xyz="22.41911e-3 -0.15798201e-3 -0.01319866e-3"/>
    </inertial>
    <visual name="palm_mesh">
      <geometry>
        <mesh filename="package://psyonic_ability_hand_model/model/meshes/FB_palm_ref_MIR.obj"/>
      </geometry>
    </visual>
    <collision>
      <geometry>
        <mesh filename="package://psyonic_ability_hand_model/model/meshes/FB_palm_ref_MIR.obj"/>
      </geometry>
      <sdf resolution="512"/>
    </collision>
  </link>
  <link name="ability_hand_ee">
    <inertial>
      <mass value="0.0004"/>
      <inertia ixx="978.26e-9" ixy="87.34e-9" ixz="322.99e-9" iyy="1244.78e-9" iyz="244.74e-9" izz="456.22e-9"/>
      <origin rpy="0 0 0" xyz="22.41911e-3 -0.15798201e-3 -0.01319866e-3"/>
    </inertial>
    <visual>
      <geometry>
        <cylinder length="0.002" radius="0.002"/>
      </geometry>
      <origin rpy="0 0 0" xyz="0.0 0.0 0.0"/>
    </visual>
  </link>
  <joint dont_collapse="true" name="ee_shifted_fix_joint" type="fixed">
    <parent link="ability_hand_base"/>
    <child link="ability_hand_ee"/>
    <!-- origin_rqy="0 3.141592653589793 3.141592653589793" origin_xyz="0 0 0.01" -->
    <!-- <origin rpy="0 0 0" xyz="-0.02 0 -0.042"/> -->
    <limit effort="2000" lower="0" upper="0" velocity="0"/>
    <!-- limit effort also defines torque limit and freeze controller gains -->
    <dynamics damping="0.0" friction="0.0"/>
  </joint>
  <!-- dummy link for hand palm -->
  <link name="palm">
    <!-- <visual>
                <origin xyz="0 0 0"/>
                <geometry>
                    <sphere radius = "0.01"/>
                </geometry>
                <material name="silver">
                    <color rgba="0.4 0.4 0.4 1"/>
                </material>
            </visual> -->
  </link>
  <joint dont_collapse="true" name="palm_joint" type="fixed">
    <parent link="ability_hand_ee"/>
    <child link="palm"/>
    <origin rpy="0.0 0.0 0.0" xyz="0.0 0.0 0.0"/>
  </joint>
  <!-- add dummy joint and link for back of the hand position -->
  <link name="back">
    <!-- <visual>
                <origin xyz="0 0 0"/>
                <geometry>
                    <sphere radius = "0.002"/>
                </geometry>
                <material name="black">
                    <color rgba="0.9 0.9 0.9 1"/>
                </material>
            </visual> -->
  </link>
  <joint dont_collapse="true" name="back_joint" type="fixed">
    <parent link="ability_hand_ee"/>
    <child link="back"/>
    <origin rpy="0.0 0.0 0.0" xyz="0.0 -0.035 0.0"/>
  </joint>
  <link name="thumb_L1">
    <inertial>
      <mass value="0.00268342"/>
      <inertia ixx="0.16931e-6" ixy="-0.076214e-6" ixz="-0.16959148e-6" iyy="0.77769934e-6" iyz="0.0156622e-6" izz="0.7249122e-6"/>
      <origin rpy="-1.5707963267948966 0 0" xyz="14.606e-3 -1.890854e-3 -3.1155356e-3"/>
    </inertial>
    <visual name="thumb_mesh_1">
      <material name="black">
        <color rgba="0.2 0.2 0.2 1"/>
      </material>
      <origin rpy=" 1.832595714594045 -0.0 5.366520605522463e-18 " xyz=" 0.0278283501 1.7436510745838653e-19 0.0147507 "/>
      <geometry>
        <mesh filename="package://psyonic_ability_hand_model/model/meshes/thumb-F1-MIR.STL"/>
      </geometry>
    </visual>
    <collision>
      <origin rpy=" 1.832595714594045 -0.0 5.366520605522463e-18 " xyz=" 0.0278283501 1.7436510745838653e-19 0.0147507 "/>
      <geometry>
        <mesh filename="package://psyonic_ability_hand_model/model/meshes/thumb-F1-MIR.STL"/>
      </geometry>
      <sdf resolution="256"/>
    </collision>
  </link>
  <link name="thumb_L2">
    <inertial>
      <mass value="0.0055"/>
      <inertia ixx="4.4789082e-6" ixy="4.4789082e-6" ixz="-0.62144934e-6" iyy="15.600996e-6" iyz="-0.07466143e-6" izz="17.908554e-6"/>
      <origin rpy="-1.5707963267948966 0 0" xyz="30.020522e-3 5.59476e-3 -4.1504356e-3"/>
    </inertial>
    <visual name="thumb_mesh_2">
      <material name="black">
        <color rgba="0.2 0.2 0.2 1"/>
      </material>
      <origin rpy="-3.141592 0 0.343830" xyz="65.18669e-3 23.34021e-3 3.93483e-3"/>
      <geometry>
        <mesh filename="package://psyonic_ability_hand_model/model/meshes/thumb-F2.STL"/>
      </geometry>
    </visual>
    <collision>
      <origin rpy="-3.141592 0 0.343830" xyz="65.18669e-3 23.34021e-3 3.93483e-3"/>
      <geometry>
        <mesh filename="package://psyonic_ability_hand_model/model/meshes/thumb-F2.STL"/>
      </geometry>
      <sdf resolution="512"/>
    </collision>
  </link>
  <joint name="thumb_q1" type="revolute">
    <parent link="ability_hand_base"/>
    <child link="thumb_L1"/>
    <origin rpy=" 3.141592653589793 -0.0 -0.18884434641020664 " xyz=" 0.0 0.0 0.0 "/>
    <axis xyz="0 0 1"/>
    <limit effort="5.0" lower="-2.0943951" upper="0" velocity="8.0677777442"/>
    <!-- angles in rad, efforts in N-m, velocity in rad/s -->
    <dynamics damping="0.001" friction="0.001"/>
    <!-- Friction coefficient is not from quantitative measurement -->
  </joint>
  <joint name="thumb_q2" type="revolute">
    <parent link="thumb_L1"/>
    <child link="thumb_L2"/>
    <origin rpy=" 1.832595714594045 -0.0 5.366520605522463e-18 " xyz=" 0.0278283501 1.7436510745838653e-19 0.0147507 "/>
    <axis xyz="0 0 -1"/>
    <limit effort="5.0" lower="0" upper="2.0943951" velocity="8.0677777442"/>
    <!-- angles in rad, efforts in N-m, velocity in rad/s -->
    <dynamics damping="0.001" friction="0.001"/>
    <!-- Friction coefficient is not from quantitative measurement -->
  </joint>
  <!-- add dummy joint and link for thumb tip position -->
  <link name="thumb_tip">
    <!-- <visual>
                <origin xyz="0 0 0"/>
                <geometry>
                    <sphere radius = "0.005"/>
                </geometry>
                <material name="silver">
                    <color rgba="0.4 0.4 0.4 1"/>
                </material>
            </visual> -->
  </link>
  <joint dont_collapse="true" name="thumb_tip_joint" type="fixed">
    <parent link="thumb_L2"/>
    <child link="thumb_tip"/>
    <origin rpy="0.0 0.0 0.0" xyz="0.05 +0.025 0.0"/>
  </joint>
  <link name="thumb_back">
    <!-- <visual>
                <origin xyz="0 0 0"/>
                <geometry>
                    <sphere radius = "0.005"/>
                </geometry>
                <material name="silver">
                    <color rgba="0.4 0.4 0.4 1"/>
                </material>
            </visual> -->
  </link>
  <joint dont_collapse="true" name="thumb_back_joint" type="fixed">
    <parent link="thumb_L2"/>
    <child link="thumb_back"/>
    <origin rpy="0.0 0.0 0.0" xyz="0.05 +0.0 0.0"/>
  </joint>
  <link name="index_L1">
    <inertial>
      <mass value="0.00635888"/>
      <inertia ixx="0.29766e-6" ixy="-0.06447133e-6" ixz="-0.00423315e-6" iyy="3.6947967e-6" iyz="0.00083028e-6" izz="3.8176336e-6"/>
      <origin rpy="0 0 0" xyz="22.41911e-3 -0.15798201e-3 -0.01319866e-3"/>
    </inertial>
    <visual name="index_mesh_1">
      <material name="black">
        <color rgba="0.2 0.2 0.2 1"/>
      </material>
      <origin rpy="0 0 0.084474" xyz="38.472723e-3 3.257695e-3 0.000000"/>
      <geometry>
        <mesh filename="package://psyonic_ability_hand_model/model/meshes/idx-F1.STL"/>
      </geometry>
    </visual>
    <collision>
      <origin rpy="0 0 0.084474" xyz="38.472723e-3 3.257695e-3 0.000000"/>
      <geometry>
        <mesh filename="package://psyonic_ability_hand_model/model/meshes/idx-F1.STL"/>
      </geometry>
      <sdf resolution="256"/>
    </collision>
  </link>
  <link name="index_L2">
    <inertial>
      <mass value="0.00645"/>
      <inertia ixx="0.82671e-6" ixy="-1.08876e-6" ixz="-0.00037e-6" iyy="1.98028e-6" iyz="0.00081e-6" izz="2.64638e-6"/>
      <origin rpy="-1.5707963267948966 0 0" xyz="13.36818e-3 -8.75392e-3 -0.02886e-3"/>
    </inertial>
    <visual name="index_mesh_2">
      <material name="black">
        <color rgba="0.2 0.2 0.2 1"/>
      </material>
      <origin rpy="0 0 0" xyz="9.1241e-3 0 0"/>
      <geometry>
        <mesh filename="package://psyonic_ability_hand_model/model/meshes/idx-F2.STL"/>
      </geometry>
    </visual>
    <collision>
      <origin rpy="0 0 0" xyz="9.1241e-3 0 0"/>
      <geometry>
        <mesh filename="package://psyonic_ability_hand_model/model/meshes/idx-F2.STL"/>
      </geometry>
      <sdf resolution="256"/>
    </collision>
  </link>
  <joint name="index_q1" type="revolute">
    <parent link="ability_hand_base"/>
    <child link="index_L1"/>
    <origin rpy=" -1.1595426535897932 1.284473 -1.0510016535897932 " xyz=" 0.00949 -0.01304 -0.06295 "/>
    <axis xyz="0 0 1"/>
    <limit effort="5.0" lower="0" upper="2.0943951" velocity="8.0677777442"/>
    <!-- angles in rad, efforts in N-m, velocity in rad/s -->
    <dynamics damping="0.001" friction="0.001"/>
    <!-- Friction coefficient is not from quantitative measurement -->
  </joint>
  <joint name="index_q2" type="revolute">
    <parent link="index_L1"/>
    <child link="index_L2"/>
    <origin rpy="0 0 0.084474" xyz="38.472723e-3 3.257695e-3 0.000000e-3"/>
    <axis xyz="0 0 1"/>
    <limit effort="5.0" lower="0.0" upper="2.6586" velocity="8.0677777442"/>
    <!-- angles in rad, efforts in N-m, velocity in rad/s -->
    <dynamics damping="0.001" friction="0.001"/>
    <!-- Friction coefficient is not from quantitative measurement -->
    <mimic joint="index_q1" multiplier="1.05851325" offset="0.72349796"/>
  </joint>
  <gazebo>
    <plugin filename="libroboticsgroup_gazebo_mimic_joint_plugin.so" name="index_q2mimic_joint_plugin">
      <joint>index_q1</joint>
      <mimicJoint>index_q2</mimicJoint>
      <multiplier>1.05851325</multiplier>
      <offset>0.72349796</offset>
      <sensitiveness>0.0</sensitiveness>
      <!-- if absolute difference between
                setpoint and process value is below this threshold, do nothing; 0.0 = disable [rad] -->
      <maxEffort>10.0</maxEffort>
    </plugin>
  </gazebo>
  <!-- add dummy link for index finger tip -->
  <link name="index_tip">
    <!-- <visual>
                <origin xyz="0 0 0"/>
                <geometry>
                    <sphere radius = "0.001"/>
                </geometry>
                <material name="black">
                    <color rgba="0.4 0.4 0.4 1"/>
                </material>
            </visual> -->
  </link>
  <joint dont_collapse="true" name="index_tip_joint" type="fixed">
    <parent link="index_L2"/>
    <child link="index_tip"/>
    <origin rpy="0.0 0.0 0.0" xyz="0.03 -0.01 0.00"/>
  </joint>
  <!-- add dummy link for back of the finger -->
  <link name="index_back">
    <!-- <visual>
                <origin xyz="0 0 0"/>
                <geometry>
                    <sphere radius = "0.001"/>
                </geometry>
                <material name="silver">
                    <color rgba="0.4 0.4 0.4 1"/>
                </material>
            </visual> -->
  </link>
  <joint dont_collapse="true" name="index_back_joint" type="fixed">
    <parent link="index_L2"/>
    <child link="index_back"/>
    <origin rpy="0.0 0.0 0.0" xyz="0.03 -0.02 0.00"/>
  </joint>
  <link name="middle_L1">
    <inertial>
      <mass value="0.00635888"/>
      <inertia ixx="0.29766e-6" ixy="-0.06447133e-6" ixz="-0.00423315e-6" iyy="3.6947967e-6" iyz="0.00083028e-6" izz="3.8176336e-6"/>
      <origin rpy="0 0 0" xyz="22.41911e-3 -0.15798201e-3 -0.01319866e-3"/>
    </inertial>
    <visual name="middle_mesh_1">
      <material name="black">
        <color rgba="0.2 0.2 0.2 1"/>
      </material>
      <origin rpy="0 0 0.084474" xyz="38.472723e-3 3.257695e-3 0.000000"/>
      <geometry>
        <mesh filename="package://psyonic_ability_hand_model/model/meshes/idx-F1.STL"/>
      </geometry>
    </visual>
    <collision>
      <origin rpy="0 0 0.084474" xyz="38.472723e-3 3.257695e-3 0.000000"/>
      <geometry>
        <mesh filename="package://psyonic_ability_hand_model/model/meshes/idx-F1.STL"/>
      </geometry>
      <sdf resolution="256"/>
    </collision>
  </link>
  <link name="middle_L2">
    <inertial>
      <mass value="0.00645"/>
      <inertia ixx="0.82671e-6" ixy="-1.08876e-6" ixz="-0.00037e-6" iyy="1.98028e-6" iyz="0.00081e-6" izz="2.64638e-6"/>
      <origin rpy="-1.5707963267948966 0 0" xyz="13.36818e-3 -8.75392e-3 -0.02886e-3"/>
    </inertial>
    <visual name="middle_mesh_2">
      <material name="black">
        <color rgba="0.2 0.2 0.2 1"/>
      </material>
      <origin rpy="0 0 0" xyz="9.1241e-3 0 0"/>
      <geometry>
        <mesh filename="package://psyonic_ability_hand_model/model/meshes/idx-F2.STL"/>
      </geometry>
    </visual>
    <collision>
      <origin rpy="0 0 0" xyz="9.1241e-3 0 0"/>
      <geometry>
        <mesh filename="package://psyonic_ability_hand_model/model/meshes/idx-F2.STL"/>
      </geometry>
      <sdf resolution="256"/>
    </collision>
  </link>
  <joint name="middle_q1" type="revolute">
    <parent link="ability_hand_base"/>
    <child link="middle_L1"/>
    <origin rpy=" -1.2810616535897934 1.308458 -1.2453756535897933 " xyz=" -0.009653191 -0.015310271 -0.067853949 "/>
    <limit effort="5.0" lower="0" upper="2.0943951" velocity="8.0677777442"/>
    <!-- angles in rad, efforts in N-m, velocity in rad/s -->
    <dynamics damping="0.001" friction="0.001"/>
    <!-- Friction coefficient is not from quantitative measurement -->
    <axis xyz="0 0 1"/>
  </joint>
  <joint name="middle_q2" type="revolute">
    <parent link="middle_L1"/>
    <child link="middle_L2"/>
    <origin rpy="0 0 0.084474" xyz="38.472723e-3 3.257695e-3 0.000000"/>
    <axis xyz="0 0 1"/>
    <limit effort="5.0" lower="0.0" upper="2.6586" velocity="8.0677777442"/>
    <!-- angles in rad, efforts in N-m, velocity in rad/s -->
    <dynamics damping="0.001" friction="0.001"/>
    <!-- Friction coefficient is not from quantitative measurement -->
    <mimic joint="middle_q1" multiplier="1.05851325" offset="0.72349796"/>
  </joint>
  <gazebo>
    <plugin filename="libroboticsgroup_gazebo_mimic_joint_plugin.so" name="middle_q2mimic_joint_plugin">
      <joint>middle_q1</joint>
      <mimicJoint>middle_q2</mimicJoint>
      <multiplier>1.05851325</multiplier>
      <offset>0.72349796</offset>
      <sensitiveness>0.0</sensitiveness>
      <!-- if absolute difference between
                setpoint and process value is below this threshold, do nothing; 0.0 = disable [rad] -->
      <maxEffort>10.0</maxEffort>
    </plugin>
  </gazebo>
  <!-- add dummy link for middle finger tip -->
  <link name="middle_tip">
    <!-- <visual>
                <origin xyz="0 0 0"/>
                <geometry>
                    <sphere radius = "0.001"/>
                </geometry>
                <material name="silver">
                    <color rgba="0.4 0.4 0.4 1"/>
                </material>
            </visual> -->
  </link>
  <joint dont_collapse="true" name="middle_tip_joint" type="fixed">
    <parent link="middle_L2"/>
    <child link="middle_tip"/>
    <origin rpy="0.0 0.0 0.0" xyz="0.03 -0.01 0.00"/>
  </joint>
  <!-- add dummy link for back of the finger -->
  <link name="middle_back">
    <!-- <visual>
                <origin xyz="0 0 0"/>
                <geometry>
                    <sphere radius = "0.001"/>
                </geometry>
                <material name="silver">
                    <color rgba="0.4 0.4 0.4 1"/>
                </material>
            </visual> -->
  </link>
  <joint dont_collapse="true" name="middle_back_joint" type="fixed">
    <parent link="middle_L2"/>
    <child link="middle_back"/>
    <origin rpy="0.0 0.0 0.0" xyz="0.03 -0.02 0.00"/>
  </joint>
  <link name="ring_L1">
    <inertial>
      <mass value="0.00635888"/>
      <inertia ixx="0.29766e-6" ixy="-0.06447133e-6" ixz="-0.00423315e-6" iyy="3.6947967e-6" iyz="0.00083028e-6" izz="3.8176336e-6"/>
      <origin rpy="0 0 0" xyz="22.41911e-3 -0.15798201e-3 -0.01319866e-3"/>
    </inertial>
    <visual name="ring_mesh_1">
      <material name="black">
        <color rgba="0.2 0.2 0.2 1"/>
      </material>
      <origin rpy="0 0 0.084474" xyz="38.472723e-3 3.257695e-3 0.000000"/>
      <geometry>
        <mesh filename="package://psyonic_ability_hand_model/model/meshes/idx-F1.STL"/>
      </geometry>
    </visual>
    <collision>
      <origin rpy="0 0 0.084474" xyz="38.472723e-3 3.257695e-3 0.000000"/>
      <geometry>
        <mesh filename="package://psyonic_ability_hand_model/model/meshes/idx-F1.STL"/>
      </geometry>
      <sdf resolution="256"/>
    </collision>
  </link>
  <link name="ring_L2">
    <inertial>
      <mass value="0.00645"/>
      <inertia ixx="0.82671e-6" ixy="-1.08876e-6" ixz="-0.00037e-6" iyy="1.98028e-6" iyz="0.00081e-6" izz="2.64638e-6"/>
      <origin rpy="-1.5707963267948966 0 0" xyz="13.36818e-3 -8.75392e-3 -0.02886e-3"/>
    </inertial>
    <visual name="ring_mesh_2">
      <material name="black">
        <color rgba="0.2 0.2 0.2 1"/>
      </material>
      <origin rpy="0 0 0" xyz="9.1241e-3 0 0"/>
      <geometry>
        <mesh filename="package://psyonic_ability_hand_model/model/meshes/idx-F2.STL"/>
      </geometry>
    </visual>
    <collision>
      <origin rpy="0 0 0" xyz="9.1241e-3 0 0"/>
      <geometry>
        <mesh filename="package://psyonic_ability_hand_model/model/meshes/idx-F2.STL"/>
      </geometry>
      <sdf resolution="256"/>
    </collision>
  </link>
  <joint name="ring_q1" type="revolute">
    <parent link="ability_hand_base"/>
    <child link="ring_L1"/>
    <origin rpy=" -1.424994653589793 1.321452 -1.4657306535897934 " xyz=" -0.02995426 -0.014212492 -0.067286105 "/>
    <limit effort="5.0" lower="0" upper="2.0943951" velocity="8.0677777442"/>
    <!-- angles in rad, efforts in N-m, velocity in rad/s -->
    <dynamics damping="0.001" friction="0.001"/>
    <!-- Friction coefficient is not from quantitative measurement -->
    <axis xyz="0 0 1"/>
  </joint>
  <joint name="ring_q2" type="revolute">
    <parent link="ring_L1"/>
    <child link="ring_L2"/>
    <origin rpy="0 0 0.084474" xyz="38.472723e-3 3.257695e-3 0.000000"/>
    <axis xyz="0 0 1"/>
    <limit effort="5.0" lower="0.0" upper="2.6586" velocity="8.0677777442"/>
    <!-- angles in rad, efforts in N-m, velocity in rad/s -->
    <dynamics damping="0.001" friction="0.001"/>
    <!-- Friction coefficient is not from quantitative measurement -->
    <mimic joint="ring_q1" multiplier="1.05851325" offset="0.72349796"/>
  </joint>
  <gazebo>
    <plugin filename="libroboticsgroup_gazebo_mimic_joint_plugin.so" name="ring_q2mimic_joint_plugin">
      <joint>ring_q1</joint>
      <mimicJoint>ring_q2</mimicJoint>
      <multiplier>1.05851325</multiplier>
      <offset>0.72349796</offset>
      <sensitiveness>0.0</sensitiveness>
      <!-- if absolute difference between
                setpoint and process value is below this threshold, do nothing; 0.0 = disable [rad] -->
      <maxEffort>10.0</maxEffort>
    </plugin>
  </gazebo>
  <!-- add dummy link for ring finger tip -->
  <link name="ring_tip">
    <!-- <visual>
                <origin xyz="0 0 0"/>
                <geometry>
                    <sphere radius = "0.001"/>
                </geometry>
                <material name="silver">
                    <color rgba="0.4 0.4 0.4 1"/>
                </material>
            </visual> -->
  </link>
  <joint dont_collapse="true" name="ring_tip_joint" type="fixed">
    <parent link="ring_L2"/>
    <child link="ring_tip"/>
    <origin rpy="0.0 0.0 0.0" xyz="0.03 -0.01 0.00"/>
  </joint>
  <!-- add dummy link for back of the finger -->
  <link name="ring_back">
    <!-- <visual>
                <origin xyz="0 0 0"/>
                <geometry>
                    <sphere radius = "0.001"/>
                </geometry>
                <material name="silver">
                    <color rgba="0.4 0.4 0.4 1"/>
                </material>
            </visual> -->
  </link>
  <joint dont_collapse="true" name="ring_back_joint" type="fixed">
    <parent link="ring_L2"/>
    <child link="ring_back"/>
    <origin rpy="0.0 0.0 0.0" xyz="0.03 -0.02 0.00"/>
  </joint>
  <link name="pinky_L1">
    <inertial>
      <mass value="0.00635888"/>
      <inertia ixx="0.29766e-6" ixy="-0.06447133e-6" ixz="-0.00423315e-6" iyy="3.6947967e-6" iyz="0.00083028e-6" izz="3.8176336e-6"/>
      <origin rpy="0 0 0" xyz="22.41911e-3 -0.15798201e-3 -0.01319866e-3"/>
    </inertial>
    <visual name="pinky_mesh_1">
      <material name="black">
        <color rgba="0.2 0.2 0.2 1"/>
      </material>
      <origin rpy="0 0 0.084474" xyz="38.472723e-3 3.257695e-3 0.000000"/>
      <geometry>
        <mesh filename="package://psyonic_ability_hand_model/model/meshes/idx-F1.STL"/>
      </geometry>
    </visual>
    <collision>
      <origin rpy="0 0 0.084474" xyz="38.472723e-3 3.257695e-3 0.000000"/>
      <geometry>
        <mesh filename="package://psyonic_ability_hand_model/model/meshes/idx-F1.STL"/>
      </geometry>
      <sdf resolution="256"/>
    </collision>
  </link>
  <link name="pinky_L2">
    <inertial>
      <mass value="0.00645"/>
      <inertia ixx="0.82671e-6" ixy="-1.08876e-6" ixz="-0.00037e-6" iyy="1.98028e-6" iyz="0.00081e-6" izz="2.64638e-6"/>
      <origin rpy="-1.5707963267948966 0 0" xyz="13.36818e-3 -8.75392e-3 -0.02886e-3"/>
    </inertial>
    <visual name="pinky_mesh_2">
      <material name="black">
        <color rgba="0.2 0.2 0.2 1"/>
      </material>
      <origin rpy="0 0 0" xyz="9.1241e-3 0 0"/>
      <geometry>
        <mesh filename="package://psyonic_ability_hand_model/model/meshes/idx-F2.STL"/>
      </geometry>
    </visual>
    <collision>
      <origin rpy="0 0 0" xyz="9.1241e-3 0 0"/>
      <geometry>
        <mesh filename="package://psyonic_ability_hand_model/model/meshes/idx-F2.STL"/>
      </geometry>
      <sdf resolution="256"/>
    </collision>
  </link>
  <joint name="pinky_q1" type="revolute">
    <parent link="ability_hand_base"/>
    <child link="pinky_L1"/>
    <origin rpy=" -1.3764826535897934 1.32222 -1.4832096535897932 " xyz=" -0.049521293 -0.011004583 -0.063029065 "/>
    <limit effort="5.0" lower="0" upper="2.0943951" velocity="8.0677777442"/>
    <!-- angles in rad, efforts in N-m, velocity in rad/s -->
    <dynamics damping="0.001" friction="0.001"/>
    <!-- Friction coefficient is not from quantitative measurement -->
    <axis xyz="0 0 1"/>
  </joint>
  <joint name="pinky_q2" type="revolute">
    <parent link="pinky_L1"/>
    <child link="pinky_L2"/>
    <origin rpy="0 0 0.084474" xyz="38.472723e-3 3.257695e-3 0.000000"/>
    <limit effort="5.0" lower="0.0" upper="2.6586" velocity="8.0677777442"/>
    <!-- angles in rad, efforts in N-m, velocity in rad/s -->
    <dynamics damping="0.001" friction="0.001"/>
    <!-- Friction coefficient is not from quantitative measurement -->
    <axis xyz="0 0 1"/>
    <mimic joint="pinky_q1" multiplier="1.05851325" offset="0.72349796"/>
  </joint>
  <gazebo>
    <plugin filename="libroboticsgroup_gazebo_mimic_joint_plugin.so" name="pinky_q2mimic_joint_plugin">
      <joint>pinky_q1</joint>
      <mimicJoint>pinky_q2</mimicJoint>
      <multiplier>1.05851325</multiplier>
      <offset>0.72349796</offset>
      <sensitiveness>0.0</sensitiveness>
      <!-- if absolute difference between
                setpoint and process value is below this threshold, do nothing; 0.0 = disable [rad] -->
      <maxEffort>10.0</maxEffort>
    </plugin>
  </gazebo>
  <!-- add dummy link for pinky finger tip -->
  <link name="pinky_tip">
    <!-- <visual>
                <origin xyz="0 0 0"/>
                <geometry>
                    <sphere radius = "0.001"/>
                </geometry>
                <material name="silver">
                    <color rgba="0.4 0.4 0.4 1"/>
                </material>
            </visual> -->
  </link>
  <joint dont_collapse="true" name="pinky_tip_joint" type="fixed">
    <parent link="pinky_L2"/>
    <child link="pinky_tip"/>
    <origin rpy="0.0 0.0 0.0" xyz="0.03 -0.01 0.00"/>
  </joint>
  <!-- add dummy link for back of the finger -->
  <link name="pinky_back">
    <!-- <visual>
                <origin xyz="0 0 0"/>
                <geometry>
                    <sphere radius = "0.001"/>
                </geometry>
                <material name="silver">
                    <color rgba="0.4 0.4 0.4 1"/>
                </material>
            </visual> -->
  </link>
  <joint dont_collapse="true" name="pinky_back_joint" type="fixed">
    <parent link="pinky_L2"/>
    <child link="pinky_back"/>
    <origin rpy="0.0 0.0 0.0" xyz="0.03 -0.02 0.00"/>
  </joint>
  <link name="index_fsr_sensor_1">
    <inertial>
      <mass value="0.00001"/>
      <inertia ixx="0.43e-10" ixy="0.0" ixz="0.0" iyy="0.43e-10" iyz="0.0" izz="0.8e-10"/>
      <origin rpy="0 0 0" xyz="0 0 0"/>
    </inertial>
    <visual name="fsr_sensor_cyl">
      <geometry>
        <cylinder length="0.002" radius="0.004"/>
      </geometry>
    </visual>
    <!--        <collision>-->
    <!--            <geometry>-->
    <!--                <cylinder length="0.002" radius="0.004"/>-->
    <!--            </geometry>-->
    <!--            <sdf resolution="32"/>-->
    <!--        </collision>-->
  </link>
  <joint dont_collapse="true" name="index_fsr_sensor_1_joint" type="fixed">
    <parent link="index_L2"/>
    <child link="index_fsr_sensor_1"/>
    <origin rpy=" 1.54752784 -0.31612134 -0.30964333 " xyz=" 0.02515633 -0.00885933 0.00073633 "/>
  </joint>
  <!-- END HAND-->
  <gazebo>
    <plugin filename="libpsyonic_controller_gazebo_plugins.so" name="ControllerGazeboPlugin">
      <hasPID/>
      <gripperPositionIncrement>0.01</gripperPositionIncrement>
      <gripperJoints>
                    index_q1
                    middle_q1
                    ring_q1
                    pinky_q1
                    thumb_q1
                    thumb_q2
                </gripperJoints>
      <passiveJoints>
                    index_q2
                    middle_q2
                    ring_q2
                    pinky_q2
                </passiveJoints>
      <jointStateTopic>/ability_hand/joint_states</jointStateTopic>
      <commandTopic>/ability_hand/joint_commands</commandTopic>
      <jointPubOrder>
                    index_q1
                    middle_q1
                    ring_q1
                    pinky_q1
                    thumb_q1
                    thumb_q2
                    index_q2
                    middle_q2
                    ring_q2
                    pinky_q2
                </jointPubOrder>
    </plugin>
  </gazebo>
</robot>
