<?xml version="1.0"?>

<!--
  Coordinate system convention for grippers:
  The pin of the gripper is along the y-axis, and z-axis points up.
  The resulting x-axis is considered the palm face, so +y is right, and -y is left for
  a right-hand gripper, whatever that means in this gripper.

  Coarse and precise models:

  Two granularities for collision are provided, a coarse (default) for quick motion
  planning purposes, and a precise for grasp simulation. This is selected with the
  boolean parameter precise_collision = true/false (default to false)

  In the same line, there is the adaptive_transmission parameter that might use
  pure mimic joints (default and motion does not consider adaptation) for visualization
  and update of real hw, and an implementation of the 5-bar transmission with
  spring transmission for grasp simulation.

  For grasp simulation, the file 2f85.gazebo.xacro sets additional parameters such as
  material properties, and simulation parameters.
-->

<robot xmlns:xacro="http://www.ros.org/wiki/xacro">

    <xacro:macro name="mimic_joint_plugin_gazebo"
        params="name_prefix parent_joint mimic_joint has_pid:=false multiplier:=1.0 offset:=0 sensitiveness:=0.0 max_effort:=1.0 robot_namespace:=''">
        <gazebo>
            <plugin name="${name_prefix}mimic_joint_plugin"
                filename="libroboticsgroup_gazebo_mimic_joint_plugin.so">
                <joint>${parent_joint}</joint>
                <mimicJoint>${mimic_joint}</mimicJoint>
                <xacro:if value="${has_pid}">                     <!-- if set to true, PID parameters from
                    "/gazebo_ros_control/pid_gains/${mimic_joint}" are loaded -->
                    <hasPID />
                </xacro:if>
                <multiplier>${multiplier}</multiplier>
                <offset>${offset}</offset>
                <sensitiveness>${sensitiveness}</sensitiveness>   <!-- if absolute difference between
                setpoint and process value is below this threshold, do nothing; 0.0 = disable [rad] -->
                <maxEffort>${max_effort}</maxEffort>              <!-- only taken into account if has_pid:=true
                [Nm] -->
                <xacro:unless value="${robot_namespace == ''}">
                    <robotNamespace>${robot_namespace}</robotNamespace>
                </xacro:unless>
            </plugin>
        </gazebo>
    </xacro:macro>


    <xacro:macro name="psyonic_ability_hand" params="parent *origin">




        <xacro:arg name="fix_finger_joints" default="true" />
        <!-- <xacro:if value="$(arg fix_finger_joints)"> -->
        <xacro:property name="finger_joint_type" value="fixed" />
        <!-- </xacro:if>
    <xacro:unless value="$(arg fix_finger_joints)"> -->
        <xacro:property name="finger_joint_type" value="revolute" />
        <!-- </xacro:unless> -->

        <!-- base -->
        <joint name="${parent}_ability_hand_wrist_connector_joint" type="fixed">
            <xacro:insert_block name="origin" />
            <parent link="${parent}" />
            <child link="wrist_connector" />
        </joint>

        <link name="wrist_connector">
            <visual name="wrist_mesh">
                <geometry>
                    <mesh filename="package://psyonic_ability_hand_model/model/meshes/wrist_mount.stl"/>
                </geometry>
            </visual>
        </link>

        <joint name="${parent}_ability_hand_base_joint" type="fixed">
            <parent link="wrist_connector" />
            <child link="ability_hand_base" />
          <origin rpy="0 0.0 0" xyz="0.027 0.0025 -0.025"/>
          <!-- <origin rpy="0 0 0" xyz="0 0 0"/> -->

        </joint>

        <!-- BEGIN HAND -->
        <link name="ability_hand_base" >
            <inertial>
                <mass value = "0.400"/>
                <inertia ixx="978.26e-6" ixy = "87.34e-6" ixz = "322.99e-6" iyy = "1244.78e-6" iyz = "244.74e-6" izz = "456.22e-6" />
                <origin xyz = "22.41911e-3 -0.15798201e-3 -0.01319866e-3" rpy = "0 0 0"/>
            </inertial>

            <visual name="palm_mesh">
                <geometry>
                    <mesh filename="package://psyonic_ability_hand_model/model/meshes/FB_palm_ref_MIR.obj"/>
                </geometry>
            </visual>
            <collision>
                <geometry>
                    <mesh filename="package://psyonic_ability_hand_model/model/meshes/FB_palm_ref_MIR.obj"/>
                </geometry>
                <sdf resolution="512"/>
            </collision>
        </link>
        <link name="ability_hand_ee" >
            <inertial>
                <mass value = "0.0004"/>
                <inertia ixx="978.26e-9" ixy = "87.34e-9" ixz = "322.99e-9" iyy = "1244.78e-9" iyz = "244.74e-9" izz = "456.22e-9" />
                <origin xyz = "22.41911e-3 -0.15798201e-3 -0.01319866e-3" rpy = "0 0 0"/>
            </inertial>
            <visual>
                <geometry>
                    <cylinder length="0.002" radius="0.002"/>
                </geometry>
                <origin xyz = "0.0 0.0 0.0" rpy = "0 0 0"/>
            </visual>
        </link>
        <joint name="ee_shifted_fix_joint" type="fixed" dont_collapse="true">
          <parent link="ability_hand_base"/>
          <child link="ability_hand_ee"/>
          <!-- origin_rqy="0 3.141592653589793 3.141592653589793" origin_xyz="0 0 0.01" -->
          <!-- <origin rpy="0 0 0" xyz="-0.02 0 -0.042"/> -->
          <limit effort="2000" lower="0" upper="0" velocity="0"/>
          <!-- limit effort also defines torque limit and freeze controller gains -->
          <dynamics damping="0.0" friction="0.0"/>
        </joint>
        <!-- dummy link for hand palm -->
        <link name = "palm" >
            <!-- <visual>
                <origin xyz="0 0 0"/>
                <geometry>
                    <sphere radius = "0.01"/>
                </geometry>
                <material name="silver">
                    <color rgba="0.4 0.4 0.4 1"/>
                </material>
            </visual> -->
        </link>
        <joint name = "palm_joint" type = "fixed" dont_collapse = "true">
            <parent link = "ability_hand_ee"/>
            <child link = "palm"/>
            <origin xyz = "0.0 0.0 0.0" rpy = "0.0 0.0 0.0"/>

        </joint>

        <!-- add dummy joint and link for back of the hand position -->
        <link name = "back" >
            <!-- <visual>
                <origin xyz="0 0 0"/>
                <geometry>
                    <sphere radius = "0.002"/>
                </geometry>
                <material name="black">
                    <color rgba="0.9 0.9 0.9 1"/>
                </material>
            </visual> -->
        </link>
        <joint name = "back_joint" type = "fixed" dont_collapse = "true">
            <parent link = "ability_hand_ee"/>
            <child link = "back"/>
            <origin xyz = "0.0 -0.035 0.0" rpy = "0.0 0.0 0.0"/>
        </joint>

        <link name="thumb_L1" >
            <inertial>
                <mass value = "0.00268342"/>
                <inertia ixx="0.16931e-6" ixy = "-0.076214e-6" ixz = "-0.16959148e-6" iyy = "0.77769934e-6" iyz = "0.0156622e-6" izz = "0.7249122e-6" />
                <origin rpy = "-1.5707963267948966 0 0" xyz = "14.606e-3 -1.890854e-3 -3.1155356e-3"/>
            </inertial>

            <visual name="thumb_mesh_1">
                <material name="black">
                    <color rgba="0.2 0.2 0.2 1"/>
                </material>
                <origin xyz = " 0.0278283501 1.7436510745838653e-19 0.0147507 " rpy = " 1.832595714594045 -0.0 5.366520605522463e-18 " />
                <geometry>
                    <mesh filename="package://psyonic_ability_hand_model/model/meshes/thumb-F1-MIR.STL"/>
                </geometry>
            </visual>
            <collision>
                <origin xyz = " 0.0278283501 1.7436510745838653e-19 0.0147507 " rpy = " 1.832595714594045 -0.0 5.366520605522463e-18 " />
                <geometry>
                    <mesh filename="package://psyonic_ability_hand_model/model/meshes/thumb-F1-MIR.STL"/>
                </geometry>
                <sdf resolution="256"/>
            </collision>
        </link>
        <link name="thumb_L2" >
            <inertial>
                <mass value = "0.0055"/>
                <inertia ixx="4.4789082e-6" ixy = "4.4789082e-6" ixz = "-0.62144934e-6" iyy = "15.600996e-6" iyz = "-0.07466143e-6" izz = "17.908554e-6" />
                <origin rpy = "-1.5707963267948966 0 0" xyz = "30.020522e-3 5.59476e-3 -4.1504356e-3"/>
            </inertial>

            <visual name="thumb_mesh_2">
                <material name="black">
                    <color rgba="0.2 0.2 0.2 1"/>
                </material>
                <origin xyz = "65.18669e-3 23.34021e-3 3.93483e-3" rpy = "-3.141592 0 0.343830"/>
                <geometry>
                    <mesh filename="package://psyonic_ability_hand_model/model/meshes/thumb-F2.STL"/>
                </geometry>
            </visual>
            <collision>
                <origin xyz = "65.18669e-3 23.34021e-3 3.93483e-3" rpy = "-3.141592 0 0.343830"/>
                <geometry>
                    <mesh filename="package://psyonic_ability_hand_model/model/meshes/thumb-F2.STL"/>
                </geometry>
                <sdf resolution="512"/>
            </collision>
        </link>
        <joint name="thumb_q1" type="revolute">
            <parent link="ability_hand_base"/>
            <child link="thumb_L1"/>
            <origin xyz = " 0.0 0.0 0.0 " rpy = " 3.141592653589793 -0.0 -0.18884434641020664 " />
            <axis xyz="0 0 1"/>
            <limit lower = "-2.0943951" upper = "0" effort = "5.0" velocity = "8.0677777442"/>        <!-- angles in rad, efforts in N-m, velocity in rad/s -->
            <dynamics damping = "0.001" friction = "0.001" />    <!-- Friction coefficient is not from quantitative measurement -->
        </joint>
        <joint name="thumb_q2" type="revolute">
            <parent link="thumb_L1"/>
            <child link="thumb_L2"/>
            <origin xyz = " 0.0278283501 1.7436510745838653e-19 0.0147507 " rpy = " 1.832595714594045 -0.0 5.366520605522463e-18 " />
            <axis xyz="0 0 -1"/>
            <limit lower = "0" upper = "2.0943951" effort = "5.0" velocity = "8.0677777442"/>        <!-- angles in rad, efforts in N-m, velocity in rad/s -->
            <dynamics damping = "0.001" friction = "0.001" />    <!-- Friction coefficient is not from quantitative measurement -->
        </joint>
        <!-- add dummy joint and link for thumb tip position -->
        <link name = "thumb_tip" >
            <!-- <visual>
                <origin xyz="0 0 0"/>
                <geometry>
                    <sphere radius = "0.005"/>
                </geometry>
                <material name="silver">
                    <color rgba="0.4 0.4 0.4 1"/>
                </material>
            </visual> -->
        </link>
        <joint name = "thumb_tip_joint" type = "fixed" dont_collapse = "true">
            <parent link = "thumb_L2"/>
            <child link = "thumb_tip"/>
            <origin xyz = "0.05 +0.025 0.0" rpy = "0.0 0.0 0.0"/>
        </joint>
        <link name = "thumb_back" >
            <!-- <visual>
                <origin xyz="0 0 0"/>
                <geometry>
                    <sphere radius = "0.005"/>
                </geometry>
                <material name="silver">
                    <color rgba="0.4 0.4 0.4 1"/>
                </material>
            </visual> -->
        </link>
        <joint name = "thumb_back_joint" type = "fixed" dont_collapse = "true">
            <parent link = "thumb_L2"/>
            <child link = "thumb_back"/>
            <origin xyz = "0.05 +0.0 0.0" rpy = "0.0 0.0 0.0"/>
        </joint>

        <link name="index_L1" >
            <inertial>
                <mass value = "0.00635888"/>
                <inertia ixx="0.29766e-6" ixy = "-0.06447133e-6" ixz = "-0.00423315e-6" iyy = "3.6947967e-6" iyz = "0.00083028e-6" izz = "3.8176336e-6" />
                <origin xyz = "22.41911e-3 -0.15798201e-3 -0.01319866e-3" rpy = "0 0 0"/>
            </inertial>
            <visual name="index_mesh_1">
                <material name="black">
                    <color rgba="0.2 0.2 0.2 1"/>
                </material>
                <origin xyz = "38.472723e-3 3.257695e-3 0.000000" rpy = "0 0 0.084474"/>
                <geometry>
                    <mesh filename="package://psyonic_ability_hand_model/model/meshes/idx-F1.STL"/>
                </geometry>
            </visual>
            <collision>
                <origin xyz = "38.472723e-3 3.257695e-3 0.000000" rpy = "0 0 0.084474"/>
                <geometry>
                    <mesh filename="package://psyonic_ability_hand_model/model/meshes/idx-F1.STL"/>
                </geometry>
                <sdf resolution="256"/>
            </collision>
        </link>
        <link name="index_L2" >
            <inertial>
                <mass value = "0.00645"/>
                <inertia ixx="0.82671e-6" ixy = "-1.08876e-6" ixz = "-0.00037e-6" iyy = "1.98028e-6" iyz = "0.00081e-6" izz = "2.64638e-6" />
                <origin rpy = "-1.5707963267948966 0 0" xyz = "13.36818e-3 -8.75392e-3 -0.02886e-3"/>
            </inertial>
            <visual name="index_mesh_2">
                <material name="black">
                    <color rgba="0.2 0.2 0.2 1"/>
                </material>
                <origin rpy = "0 0 0" xyz = "9.1241e-3 0 0"/>
                <geometry>
                    <mesh filename="package://psyonic_ability_hand_model/model/meshes/idx-F2.STL"/>
                </geometry>
            </visual>
            <collision>
                <origin rpy = "0 0 0" xyz = "9.1241e-3 0 0"/>
                <geometry>
                    <mesh filename="package://psyonic_ability_hand_model/model/meshes/idx-F2.STL"/>
                </geometry>
                <sdf resolution="256"/>
            </collision>
        </link>
        <joint name="index_q1" type="revolute">
            <parent link="ability_hand_base"/>
            <child link="index_L1"/>
            <origin xyz = " 0.00949 -0.01304 -0.06295 " rpy = " -1.1595426535897932 1.284473 -1.0510016535897932 " />
            <axis xyz="0 0 1"/>
            <limit lower = "0" upper = "2.0943951" effort = "5.0" velocity = "8.0677777442"/>        <!-- angles in rad, efforts in N-m, velocity in rad/s -->
            <dynamics damping = "0.001" friction = "0.001" />    <!-- Friction coefficient is not from quantitative measurement -->
        </joint>
        <joint name="index_q2" type="revolute">
            <parent link="index_L1"/>
            <child link="index_L2"/>
            <origin xyz = "38.472723e-3 3.257695e-3 0.000000e-3" rpy = "0 0 0.084474"/>
            <axis xyz="0 0 1"/>
            <limit lower = "0.0" upper = "2.6586" effort = "5.0" velocity = "8.0677777442"/>        <!-- angles in rad, efforts in N-m, velocity in rad/s -->
            <dynamics damping = "0.001" friction = "0.001" />    <!-- Friction coefficient is not from quantitative measurement -->
            <mimic joint = "index_q1" multiplier =  "1.05851325" offset = "0.72349796"/>
        </joint>

        <xacro:mimic_joint_plugin_gazebo name_prefix="index_q2"
            parent_joint="index_q1" mimic_joint="index_q2"
            has_pid="false" multiplier="1.05851325" max_effort="10.0" offset="0.72349796" />
        <!-- add dummy link for index finger tip -->
        <link name = "index_tip" >
            <!-- <visual>
                <origin xyz="0 0 0"/>
                <geometry>
                    <sphere radius = "0.001"/>
                </geometry>
                <material name="black">
                    <color rgba="0.4 0.4 0.4 1"/>
                </material>
            </visual> -->
        </link>
        <joint name = "index_tip_joint" type = "fixed" dont_collapse = "true">
            <parent link = "index_L2"/>
            <child link = "index_tip"/>
            <origin xyz = "0.03 -0.01 0.00" rpy = "0.0 0.0 0.0"/>
        </joint>
        <!-- add dummy link for back of the finger -->
        <link name = "index_back" >
            <!-- <visual>
                <origin xyz="0 0 0"/>
                <geometry>
                    <sphere radius = "0.001"/>
                </geometry>
                <material name="silver">
                    <color rgba="0.4 0.4 0.4 1"/>
                </material>
            </visual> -->
        </link>
        <joint name = "index_back_joint" type = "fixed" dont_collapse = "true">
            <parent link = "index_L2"/>
            <child link = "index_back"/>
            <origin xyz = "0.03 -0.02 0.00" rpy = "0.0 0.0 0.0"/>
        </joint>

        <link name="middle_L1" >
            <inertial>
                <mass value = "0.00635888"/>
                <inertia ixx="0.29766e-6" ixy = "-0.06447133e-6" ixz = "-0.00423315e-6" iyy = "3.6947967e-6" iyz = "0.00083028e-6" izz = "3.8176336e-6" />
                <origin xyz = "22.41911e-3 -0.15798201e-3 -0.01319866e-3" rpy = "0 0 0"/>
            </inertial>

            <visual name="middle_mesh_1">
                <material name="black">
                    <color rgba="0.2 0.2 0.2 1"/>
                </material>
                <origin xyz = "38.472723e-3 3.257695e-3 0.000000" rpy = "0 0 0.084474"/>
                <geometry>
                    <mesh filename="package://psyonic_ability_hand_model/model/meshes/idx-F1.STL"/>
                </geometry>
            </visual>
            <collision>
                <origin xyz = "38.472723e-3 3.257695e-3 0.000000" rpy = "0 0 0.084474"/>
                <geometry>
                    <mesh filename="package://psyonic_ability_hand_model/model/meshes/idx-F1.STL"/>
                </geometry>
                <sdf resolution="256"/>
            </collision>
        </link>
        <link name="middle_L2" >
            <inertial>
                <mass value = "0.00645"/>
                <inertia ixx="0.82671e-6" ixy = "-1.08876e-6" ixz = "-0.00037e-6" iyy = "1.98028e-6" iyz = "0.00081e-6" izz = "2.64638e-6" />
                <origin rpy = "-1.5707963267948966 0 0" xyz = "13.36818e-3 -8.75392e-3 -0.02886e-3"/>
            </inertial>
            <visual name="middle_mesh_2">
                <material name="black">
                    <color rgba="0.2 0.2 0.2 1"/>
                </material>
                <origin rpy = "0 0 0" xyz = "9.1241e-3 0 0"/>
                <geometry>
                    <mesh filename="package://psyonic_ability_hand_model/model/meshes/idx-F2.STL"/>
                </geometry>
            </visual>
            <collision>
                <origin rpy = "0 0 0" xyz = "9.1241e-3 0 0"/>
                <geometry>
                    <mesh filename="package://psyonic_ability_hand_model/model/meshes/idx-F2.STL"/>
                </geometry>
                <sdf resolution="256"/>
            </collision>
        </link>
        <joint name="middle_q1" type="revolute">
            <parent link="ability_hand_base"/>
            <child link="middle_L1"/>
            <origin xyz = " -0.009653191 -0.015310271 -0.067853949 " rpy = " -1.2810616535897934 1.308458 -1.2453756535897933 " />
            <limit lower = "0" upper = "2.0943951" effort = "5.0" velocity = "8.0677777442"/>        <!-- angles in rad, efforts in N-m, velocity in rad/s -->
            <dynamics damping = "0.001" friction = "0.001" />    <!-- Friction coefficient is not from quantitative measurement -->
            <axis xyz="0 0 1"/>
        </joint>
        <joint name="middle_q2" type="revolute">
            <parent link="middle_L1"/>
            <child link="middle_L2"/>
            <origin xyz = "38.472723e-3 3.257695e-3 0.000000" rpy = "0 0 0.084474"/>
            <axis xyz="0 0 1"/>
            <limit lower = "0.0" upper = "2.6586" effort = "5.0" velocity = "8.0677777442"/>        <!-- angles in rad, efforts in N-m, velocity in rad/s -->
            <dynamics damping = "0.001" friction = "0.001" />    <!-- Friction coefficient is not from quantitative measurement -->
            <mimic joint = "middle_q1" multiplier =  "1.05851325" offset = "0.72349796"/>
        </joint>

        <xacro:mimic_joint_plugin_gazebo name_prefix="middle_q2"
            parent_joint="middle_q1" mimic_joint="middle_q2"
            has_pid="false" multiplier="1.05851325" max_effort="10.0" offset="0.72349796" />
        <!-- add dummy link for middle finger tip -->
        <link name = "middle_tip" >
            <!-- <visual>
                <origin xyz="0 0 0"/>
                <geometry>
                    <sphere radius = "0.001"/>
                </geometry>
                <material name="silver">
                    <color rgba="0.4 0.4 0.4 1"/>
                </material>
            </visual> -->
        </link>
        <joint name = "middle_tip_joint" type = "fixed" dont_collapse = "true">
            <parent link = "middle_L2"/>
            <child link = "middle_tip"/>
            <origin xyz = "0.03 -0.01 0.00" rpy = "0.0 0.0 0.0"/>
        </joint>
        <!-- add dummy link for back of the finger -->
        <link name = "middle_back" >
            <!-- <visual>
                <origin xyz="0 0 0"/>
                <geometry>
                    <sphere radius = "0.001"/>
                </geometry>
                <material name="silver">
                    <color rgba="0.4 0.4 0.4 1"/>
                </material>
            </visual> -->
        </link>
        <joint name = "middle_back_joint" type = "fixed" dont_collapse = "true">
            <parent link = "middle_L2"/>
            <child link = "middle_back"/>
            <origin xyz = "0.03 -0.02 0.00" rpy = "0.0 0.0 0.0"/>
        </joint>

        <link name="ring_L1" >
            <inertial>
                <mass value = "0.00635888"/>
                <inertia ixx="0.29766e-6" ixy = "-0.06447133e-6" ixz = "-0.00423315e-6" iyy = "3.6947967e-6" iyz = "0.00083028e-6" izz = "3.8176336e-6" />
                <origin xyz = "22.41911e-3 -0.15798201e-3 -0.01319866e-3" rpy = "0 0 0"/>
            </inertial>

            <visual name="ring_mesh_1">
                <material name="black">
                    <color rgba="0.2 0.2 0.2 1"/>
                </material>
                <origin xyz = "38.472723e-3 3.257695e-3 0.000000" rpy = "0 0 0.084474"/>
                <geometry>
                    <mesh filename="package://psyonic_ability_hand_model/model/meshes/idx-F1.STL"/>
                </geometry>
            </visual>
            <collision>
                <origin xyz = "38.472723e-3 3.257695e-3 0.000000" rpy = "0 0 0.084474"/>
                <geometry>
                    <mesh filename="package://psyonic_ability_hand_model/model/meshes/idx-F1.STL"/>
                </geometry>
                <sdf resolution="256"/>
            </collision>
        </link>
        <link name="ring_L2" >
            <inertial>
                <mass value = "0.00645"/>
                <inertia ixx="0.82671e-6" ixy = "-1.08876e-6" ixz = "-0.00037e-6" iyy = "1.98028e-6" iyz = "0.00081e-6" izz = "2.64638e-6" />
                <origin rpy = "-1.5707963267948966 0 0" xyz = "13.36818e-3 -8.75392e-3 -0.02886e-3"/>
            </inertial>
            <visual name="ring_mesh_2">
                <material name="black">
                    <color rgba="0.2 0.2 0.2 1"/>
                </material>
                <origin rpy = "0 0 0" xyz = "9.1241e-3 0 0"/>
                <geometry>
                    <mesh filename="package://psyonic_ability_hand_model/model/meshes/idx-F2.STL"/>
                </geometry>
            </visual>
            <collision>
                <origin rpy = "0 0 0" xyz = "9.1241e-3 0 0"/>
                <geometry>
                    <mesh filename="package://psyonic_ability_hand_model/model/meshes/idx-F2.STL"/>
                </geometry>
                <sdf resolution="256"/>
            </collision>
        </link>
        <joint name="ring_q1" type="revolute">
            <parent link="ability_hand_base"/>
            <child link="ring_L1"/>
            <origin xyz = " -0.02995426 -0.014212492 -0.067286105 " rpy = " -1.424994653589793 1.321452 -1.4657306535897934 " />
            <limit lower = "0" upper = "2.0943951" effort = "5.0" velocity = "8.0677777442"/>        <!-- angles in rad, efforts in N-m, velocity in rad/s -->
            <dynamics damping = "0.001" friction = "0.001" />    <!-- Friction coefficient is not from quantitative measurement -->
            <axis xyz="0 0 1"/>
        </joint>
        <joint name="ring_q2" type="revolute">
            <parent link="ring_L1"/>
            <child link="ring_L2"/>
            <origin xyz = "38.472723e-3 3.257695e-3 0.000000" rpy = "0 0 0.084474"/>
            <axis xyz="0 0 1"/>
            <limit lower = "0.0" upper = "2.6586" effort = "5.0" velocity = "8.0677777442"/>        <!-- angles in rad, efforts in N-m, velocity in rad/s -->
            <dynamics damping = "0.001" friction = "0.001" />    <!-- Friction coefficient is not from quantitative measurement -->
            <mimic joint = "ring_q1" multiplier =  "1.05851325" offset = "0.72349796"/>
        </joint>

        <xacro:mimic_joint_plugin_gazebo name_prefix="ring_q2"
            parent_joint="ring_q1" mimic_joint="ring_q2"
            has_pid="false" multiplier="1.05851325" max_effort="10.0" offset="0.72349796" />
        <!-- add dummy link for ring finger tip -->
        <link name = "ring_tip" >
            <!-- <visual>
                <origin xyz="0 0 0"/>
                <geometry>
                    <sphere radius = "0.001"/>
                </geometry>
                <material name="silver">
                    <color rgba="0.4 0.4 0.4 1"/>
                </material>
            </visual> -->
        </link>
        <joint name = "ring_tip_joint" type = "fixed" dont_collapse = "true">
            <parent link = "ring_L2"/>
            <child link = "ring_tip"/>
            <origin xyz = "0.03 -0.01 0.00" rpy = "0.0 0.0 0.0"/>
        </joint>
        <!-- add dummy link for back of the finger -->
        <link name = "ring_back" >
            <!-- <visual>
                <origin xyz="0 0 0"/>
                <geometry>
                    <sphere radius = "0.001"/>
                </geometry>
                <material name="silver">
                    <color rgba="0.4 0.4 0.4 1"/>
                </material>
            </visual> -->
        </link>
        <joint name = "ring_back_joint" type = "fixed" dont_collapse = "true">
            <parent link = "ring_L2"/>
            <child link = "ring_back"/>
            <origin xyz = "0.03 -0.02 0.00" rpy = "0.0 0.0 0.0"/>
        </joint>

        <link name="pinky_L1" >
            <inertial>
                <mass value = "0.00635888"/>
                <inertia ixx="0.29766e-6" ixy = "-0.06447133e-6" ixz = "-0.00423315e-6" iyy = "3.6947967e-6" iyz = "0.00083028e-6" izz = "3.8176336e-6" />
                <origin xyz = "22.41911e-3 -0.15798201e-3 -0.01319866e-3" rpy = "0 0 0"/>
            </inertial>

            <visual name="pinky_mesh_1">
                <material name="black">
                    <color rgba="0.2 0.2 0.2 1"/>
                </material>
                <origin xyz = "38.472723e-3 3.257695e-3 0.000000" rpy = "0 0 0.084474"/>
                <geometry>
                    <mesh filename="package://psyonic_ability_hand_model/model/meshes/idx-F1.STL"/>
                </geometry>
            </visual>
            <collision>
                <origin xyz = "38.472723e-3 3.257695e-3 0.000000" rpy = "0 0 0.084474"/>
                <geometry>
                    <mesh filename="package://psyonic_ability_hand_model/model/meshes/idx-F1.STL"/>
                </geometry>
                <sdf resolution="256"/>
            </collision>
        </link>
        <link name="pinky_L2" >
            <inertial>
                <mass value = "0.00645"/>
                <inertia ixx="0.82671e-6" ixy = "-1.08876e-6" ixz = "-0.00037e-6" iyy = "1.98028e-6" iyz = "0.00081e-6" izz = "2.64638e-6" />
                <origin rpy = "-1.5707963267948966 0 0" xyz = "13.36818e-3 -8.75392e-3 -0.02886e-3"/>
            </inertial>
            <visual name="pinky_mesh_2">
                <material name="black">
                    <color rgba="0.2 0.2 0.2 1"/>
                </material>
                <origin rpy = "0 0 0" xyz = "9.1241e-3 0 0"/>
                <geometry>
                    <mesh filename="package://psyonic_ability_hand_model/model/meshes/idx-F2.STL"/>
                </geometry>
            </visual>
            <collision>
                <origin rpy = "0 0 0" xyz = "9.1241e-3 0 0"/>
                <geometry>
                    <mesh filename="package://psyonic_ability_hand_model/model/meshes/idx-F2.STL"/>
                </geometry>
                <sdf resolution="256"/>
            </collision>
        </link>
        <joint name="pinky_q1" type="revolute">
            <parent link="ability_hand_base"/>
            <child link="pinky_L1"/>
            <origin xyz = " -0.049521293 -0.011004583 -0.063029065 " rpy = " -1.3764826535897934 1.32222 -1.4832096535897932 " />
            <limit lower = "0" upper = "2.0943951" effort = "5.0" velocity = "8.0677777442"/>        <!-- angles in rad, efforts in N-m, velocity in rad/s -->
            <dynamics damping = "0.001" friction = "0.001" />    <!-- Friction coefficient is not from quantitative measurement -->
            <axis xyz="0 0 1"/>
        </joint>
        <joint name="pinky_q2" type="revolute">
            <parent link="pinky_L1"/>
            <child link="pinky_L2"/>
            <origin xyz = "38.472723e-3 3.257695e-3 0.000000" rpy = "0 0 0.084474"/>
            <limit lower = "0.0" upper = "2.6586" effort = "5.0" velocity = "8.0677777442"/>        <!-- angles in rad, efforts in N-m, velocity in rad/s -->
            <dynamics damping = "0.001" friction = "0.001" />    <!-- Friction coefficient is not from quantitative measurement -->
            <axis xyz="0 0 1"/>
            <mimic joint = "pinky_q1" multiplier =  "1.05851325" offset = "0.72349796"/>
        </joint>


        <xacro:mimic_joint_plugin_gazebo name_prefix="pinky_q2"
            parent_joint="pinky_q1" mimic_joint="pinky_q2"
            has_pid="false" multiplier="1.05851325" max_effort="10.0" offset="0.72349796" />
        <!-- add dummy link for pinky finger tip -->
        <link name = "pinky_tip" >
            <!-- <visual>
                <origin xyz="0 0 0"/>
                <geometry>
                    <sphere radius = "0.001"/>
                </geometry>
                <material name="silver">
                    <color rgba="0.4 0.4 0.4 1"/>
                </material>
            </visual> -->
        </link>
        <joint name = "pinky_tip_joint" type = "fixed" dont_collapse = "true">
            <parent link = "pinky_L2"/>
            <child link = "pinky_tip"/>
            <origin xyz = "0.03 -0.01 0.00" rpy = "0.0 0.0 0.0"/>
        </joint>
        <!-- add dummy link for back of the finger -->
        <link name = "pinky_back" >
            <!-- <visual>
                <origin xyz="0 0 0"/>
                <geometry>
                    <sphere radius = "0.001"/>
                </geometry>
                <material name="silver">
                    <color rgba="0.4 0.4 0.4 1"/>
                </material>
            </visual> -->
        </link>
        <joint name = "pinky_back_joint" type = "fixed" dont_collapse = "true">
            <parent link = "pinky_L2"/>
            <child link = "pinky_back"/>
            <origin xyz = "0.03 -0.02 0.00" rpy = "0.0 0.0 0.0"/>
        </joint>

        <link name="index_fsr_sensor_1">
            <inertial>
                <mass value = "0.00001"/>
                <inertia ixx="0.43e-10" ixy = "0.0" ixz = "0.0" iyy = "0.43e-10" iyz = "0.0" izz = "0.8e-10" />
                <origin rpy = "0 0 0" xyz = "0 0 0"/>
            </inertial>
            <visual name="fsr_sensor_cyl">
                <geometry>
                    <cylinder length="0.002" radius="0.004"/>
                </geometry>
            </visual>
    <!--        <collision>-->
    <!--            <geometry>-->
    <!--                <cylinder length="0.002" radius="0.004"/>-->
    <!--            </geometry>-->
    <!--            <sdf resolution="32"/>-->
    <!--        </collision>-->
        </link>
        <joint name="index_fsr_sensor_1_joint" type="fixed" dont_collapse="true">
            <parent link="index_L2"/>
            <child link="index_fsr_sensor_1"/>
            <origin xyz = " 0.02515633 -0.00885933 0.00073633 " rpy = " 1.54752784 -0.31612134 -0.30964333 " />
        </joint>

        <!-- END HAND-->

        <gazebo>
            <plugin name="ControllerGazeboPlugin" filename="libpsyonic_controller_gazebo_plugins.so">
                <hasPID />
                <gripperPositionIncrement>0.01</gripperPositionIncrement>
                <gripperJoints>
                    index_q1
                    middle_q1
                    ring_q1
                    pinky_q1
                    thumb_q1
                    thumb_q2
                </gripperJoints>
                <passiveJoints>
                    index_q2
                    middle_q2
                    ring_q2
                    pinky_q2
                </passiveJoints>
                <jointStateTopic>/ability_hand/joint_states</jointStateTopic>
                <commandTopic>/ability_hand/joint_commands</commandTopic>
                <jointPubOrder>
                    index_q1
                    middle_q1
                    ring_q1
                    pinky_q1
                    thumb_q1
                    thumb_q2
                    index_q2
                    middle_q2
                    ring_q2
                    pinky_q2
                </jointPubOrder>
            </plugin>
        </gazebo>

    </xacro:macro>
</robot>
